<h1>详解恐慌和恢复原理</h1>

<p><b><i>
（注意：这是本文的旧版本。此版本认为普通恐慌和Goexit信号是相互独立的。
我个人认为这种解释是合理的，但是此解释和官方标准运行时的实现不一致。
在发布Go工具链1.19版本之前，Go核心团队澄清了官方标准运行时的实现是没问题的。
换句话说，此澄清认为一个Goexit信号应该被视为一个无害的不可恢复的恐慌，
请阅读<a href="panic-and-recover-more.html">采纳了此澄清的新版本</a>。）
</i></b></p>

<p>
恐慌和恢复原理已经在前面的文章中<a href="control-flows-more.html#panic-recover">介绍过了</a>。
一些恐慌和恢复用例也在<a href="panic-and-recover-use-cases.html">上一篇文章中</a>得到了展示。
本文将详细解释一下恐慌和恢复原理。函数调用的退出阶段也将被一并详细解释。
</p>

<a class="anchor" id="exiting-phase"></a>
<h3>函数调用的退出阶段</h3>

<div>
<p>
在Go中，一个函数调用在其退出完毕之前可能将经历一个退出阶段。
在此退出阶段，所有在执行此函数调用期间被推入延迟调用队列的延迟函数调用将按照它们的推入顺序的逆序被执行。
当这些延迟函数调用都退出完毕之后，此函数调用的退出阶段也就结束了，或者说此函数调用也退出完毕了，
</p>

<p>
退出阶段有时候也被称为返回阶段。
</p>

一个函数调用可能通过三种途径进入它的退出阶段：
<ol>
<li>
	此调用正常返回；
</li>
<li>
	当此调用中产生了一个恐慌；
</li>
<li>
	当<code>runtime.Goexit</code>函数在此调用中被调用并且退出完毕。
</li>
</ol>

比如，在下面这段代码中，
<ul>
<li>
	函数<code>f0</code>或者<code>f1</code>的一个调用将在它正常返回后进入它的退出阶段；
</li>
<li>
	函数<code>f2</code>的一个调用将在“被零除”恐慌产生之后进入它的退出阶段；
</li>
<li>
	函数<code>f3</code>的一个调用将在其中的<code>runtime.Goexit</code>函数调用退出完毕之后进入它的退出阶段。
</li>
</ul>

<pre class="line-numbers"><code class="language-go">import (
	"fmt"
	"runtime"
)

func f0() int {
	var x = 1
	defer fmt.Println("正常退出：", x)
	x++
	return x
}

func f1() {
	var x = 1
	defer fmt.Println("正常退出：", x)
	x++
}

func f2() {
	var x, y = 1, 0
	defer fmt.Println("因恐慌而退出：", x)
	x = x / y // 将产生一个恐慌
	x++       // 执行不到
}

func f3() int {
	x := 1
	defer fmt.Println("因Goexit调用而退出：", x)
	x++
	runtime.Goexit()
	return x+x // 执行不到
}
</code></pre>

<p>
</p>
</div>

<a class="anchor" id="function-call-assosiations"></a>
<h3>函数调用关联恐慌和Goexit信号</h3>
<div>

<p><b><i>
（重申一次：本节中的解释和官方标准运行时的实现不一致。
请阅读<a href="panic-and-recover-more.html">和官方标准运行时的实现一致的版本</a>。）
</i></b></p>

<p>
当一个函数调用中直接产生了一个恐慌的时候，我们可以认为此（尚未被恢复的）恐慌将和此函数调用相关联起来。
类似地，当一个函数调用直接调用了<code>runtime.Goexit</code>函数，则<code>runtime.Goexit</code>函数返回完毕之后，我们可以认为一个Goexit信号将和此函数调用相关联起来。
恐慌和Goexit信号互相独立于对方，两者互不干扰。
按照上一节中的解释，当一个恐慌或者一个Goexit信号和一个函数调用相关联之后，此函数调用将立即进入它的退出阶段。
</p>

<p>
我们已经了解到<a href="control-flows-more.html#panic-recover">恐慌是可以被恢复的</a>。
但是，Goexit信号是不能被取消的。
</p>

在任何一个给定时刻，一个函数调用最多只能和一个未恢复的恐慌相关联。
如果一个调用正和一个未恢复的恐慌相关联，则
<ul>
<li>
	在此恐慌被恢复之后，此调用将不再和任何恐慌相关联。
</li>
<li>
	当在此函数调用中产生了一个新的恐慌，此新恐慌将替换原来的未被恢复的恐慌做为和此函数调用相关联的恐慌。
</li>
</ul>

比如，在下面这个例子中，最终被恢复的恐慌是恐慌3。它是最后一个和<code>main</code>函数调用相关联的恐慌。

<pre class="line-numbers"><code class="language-go">package main

import "fmt"

func main() {
	defer func() {
		fmt.Println(recover()) // 3
	}()
	
	defer panic(3) // 将替换恐慌2
	defer panic(2) // 将替换恐慌1
	defer panic(1) // 将替换恐慌0
	panic(0)
}
</code></pre>

<p>
</p>

<p>
因为Goexit信号不可被取消，争论一个函数调用是否最多只能和一个Goexit信号相关联是没有意义和没有必要的。
</p>

在某个时刻，一个协程中可能共存多个未被恢复的恐慌，尽管这在实际编程中并不常见。
每个未被恢复的恐慌和此协程的调用堆栈中的一个尚未退出的函数调用相关联。
当仍和一个未被恢复的恐慌相关联的一个内层函数调用退出完毕之后，此未被恢复的恐慌将传播到调用此内层函数调用的外层函数调用中。
这和在此外层函数调用中直接产生一个新的恐慌的效果是一样的。也就是说，
<ul>
<li>
	如果此外层函数已经和一个未被恢复的旧恐慌相关联，则传播出来的新恐慌将替换此旧恐慌并和此外层函数调用相关联起来。
	对于这种情形，此外层函数调用肯定已经进入了它的退出阶段（刚提及的内层函数肯定就是被延迟调用的），这时延迟调用队列中的下一个延迟调用将被执行。
</li>
<li>
	如果此外层函数尚未和一个未被恢复的旧恐慌相关联，则传播出来的恐慌将和此外层函数调用相关联起来。
	对于这种情形，如果此外层函数调用尚未进入它的退出阶段，则它将立即进入。
</li>
</ul>

<p>
所以，当一个协程完成完毕后，此协程中最多只有一个尚未被恢复的恐慌。
如果一个协程带着一个尚未被恢复的恐慌退出完毕，则这将使整个程序崩溃，此恐慌信息将在程序崩溃的时候被打印出来。
</p>

<p>
在一个函数调用被执行的起始时刻，此调用将没有任何恐慌和Goexit信号和它相关联，这个事实和此函数调用的外层调用是否已经进入退出阶段无关。
当然，在此函数调用的执行过程中，恐慌可能产生，<code>runtime.Goexit</code>函数也可能被调用，因此恐慌和Goexit信号以后可能和此调用相关联起来。
</p>

下面这个例子程序在运行时将崩溃，因为新开辟的协程在退出完毕时仍带有一个未被恢复的恐慌。

<pre class="line-numbers"><code class="language-go">package main

func main() {
	// 新开辟一个协程。
	go func() {
		// 一个匿名函数调用。
		// 当它退出完毕时，恐慌2将传播到此新协程的入口
		// 调用中，并且替换掉恐慌0。恐慌2永不会被恢复。
		defer func() {
			// 上一个例子中已经解释过了：恐慌2将替换恐慌1.
			defer panic(2)
			
			// 当此匿名函数调用退出完毕后，恐慌1将传播到刚
			// 提到的外层匿名函数调用中并与之关联起来。
			func () {
				panic(1)
				// 在恐慌1产生后，此新开辟的协程中将共存
				// 两个未被恢复的恐慌。其中一个（恐慌0）
				// 和此协程的入口函数调用相关联；另一个
				// （恐慌1）和当前这个匿名调用相关联。
			}()
		}()
		panic(0)
	}()
	
	select{}
}
</code></pre>

此程序的输出（当使用标准编译器1.19版本编译）：
<pre class="output"><code>panic: 0
	panic: 1
	panic: 2

goroutine 5 [running]:
...
</code></pre>

<p>
此输出的格式并非很完美，它容易让一些程序员误认为恐慌0是最终未被恢复的恐慌。而事实上，恐慌2才是最终未被恢复的恐慌。
</p>

<p>
类似地，当一个和Goexit信号相关联的内层函数调用退出完毕后，此Goexit信号也将传播到外层函数调用中，并和外层函数调用相关联起来。
如果外层函数调用尚未进入退出阶段，则其将立即进入。
</p>

上面提到了恐慌和Goexit信号是互不干扰的。
换句话说，一个尚未被恢复的恐慌不会导致一个Goexit信号被取消；一个Goexit信号也不会压制遮挡一个尚未被恢复的恐慌。
不过目前最新版本的官方两个编译器（标准编译器v1.19和gccgo v10）都并未正确实现此规则。
比如，下面这个程序本应崩溃退出，但是并没有（使用最新版本的标准编译器和gccgo编译器编译）。

<pre class="line-numbers"><code class="language-go">package main

import "runtime"

func f() {
	// 此调用产生的Goexit信号将压制先前
	// 产生的恐慌"bye"，但是不应该如此。
	defer runtime.Goexit()
	panic("bye")
}

func main() {
	go f()
	
	for runtime.NumGoroutine() > 1 {
		runtime.Gosched()
	}
}
</code></pre>

<p>
标准编译器和gccgo编译器将在以后的版本中修复<a href="https://github.com/golang/go/issues/35378">此问题</a>。
</p>

下面这个例子程序运行时应该马上退出，但是当前版本的gccgo编译器（v8.0）和Go官方工具链1.14之前的官方标准编译器均未正确实现之，从而导致此程序在运行时永不退出。

<pre class="line-numbers"><code class="language-go">package main

import "runtime"

func f() {
	defer func() {
		recover()
	}()
	defer panic("将取消Goexit信号但是不应该这样")
	runtime.Goexit()
}

func main() {
	c := make(chan struct{})
	go func() {
		defer close(c)
		f()
		for {
			runtime.Gosched()
		}
	}()
	<-c
}
</code></pre>

<p>
标准编译器从1.14版本开始修复了<a href="https://github.com/golang/go/issues/29226">此问题</a>。
</p>

</div>

<a class="anchor" id="some-recovers-are-no-ops"></a>
<h3>一些<code>recover</code>调用相当于空操作（No-Op）</h3>
<div>

内置<code>recover</code>函数必须在合适的位置调用才能发挥作用；否则，它的调用相当于空操作。
比如，在下面这个程序中，没有一个<code>recover</code>函数调用恢复了恐慌<code>bye</code>。

<pre class="line-numbers"><code class="language-go">package main

func main() {
	defer func() {
		defer func() {
			recover() // 空操作
		}()
	}()
	defer func() {
		func() {
			recover() // 空操作
		}()
	}()
	func() {
		defer func() {
			recover() // 空操作
		}()
	}()
	func() {
		defer recover() // 空操作
	}()
	func() {
		recover() // 空操作
	}()
	recover()       // 空操作
	defer recover() // 空操作
	panic("bye")
}
</code></pre>

<p>
</p>

我们已经知道下面这个<code>recover</code>调用是有作用的。

<pre class="line-numbers"><code class="language-go">package main

func main() {
	defer func() {
		recover() // 将恢复恐慌"byte"
	}()

	panic("bye")
}
</code></pre>

<p>
</p>

那么为什么本节中的第一个例子中的所有<code>recover</code>调用都不起作用呢？
让我们先看看当前版本的<a href="https://golang.org/ref/spec#Handling_panics">Go白皮书</a>是怎么说的：

<div class="alert alert-success">
在下面的情况下，<code>recover</code>函数调用的返回值为<code>nil</code>：
<ul>
<li>传递给相应<code>panic</code>函数调用的实参为nil；</li>
<li>当前协程并没有处于恐慌状态；</li>
<li><code>recover</code>函数并未直接在一个延迟函数调用中调用。</li>
</ul>
</div>

<p>
上一篇文章中提供了<a href="panic-and-recover-use-cases.html#avoid-verbose">一个第一种情况的例子</a>。
</p>

<p>
本节中的第一个例子中的大多<code>recover</code>调用要么符合Go白皮书中描述的第二种情况，要么符合第三种情况，除了第一个<code>recover</code>调用。
是的，当前版本的白皮书中的描述并不准确。此描述正<a href="https://go-review.googlesource.com/c/go/+/189377">在被改进中</a>。
</p>

事实上，当前版本的白皮书也没有解释清楚为什么下面这个例子中的第二个<code>recover</code>调用没有起作用。此调用本用来恢复恐慌1。

<pre class="line-numbers"><code class="language-go">// 此程序将带着未被恢复的恐慌1而崩溃退出。
package main

func demo() {
	defer func() {
		defer func() {
			recover() // 此调用将恢复恐慌2
		}()

		defer recover() // 空操作

		panic(2)
	}()
	panic(1)
}

func main() {
	demo()
}
</code></pre>

<p>
当前版本的白皮书没提到的一点是：在任何时刻，一个协程中只有最新产生的恐慌才能够被恢复。
换句话说，每个<code>recover</code>调用都试图恢复当前协程中最新产生的且尚未恢复的恐慌。
这解释了为什么上例中的第二个<code>recover</code>调用不会起作用。
</p>

好了，到此我们可以对哪些<code>recover</code>调用会起作用做一个简短的描述：
<div class="alert alert-warning">
一个<code>recover</code>调用只有在它的直接外层调用（即<code>recover</code>调用的父调用）是一个延迟调用，并且此延迟调用（即父调用）的直接外层调用（即<code>recover</code>调用的爷调用）和当前协程中最新产生并且尚未恢复的恐慌相关联时才起作用。一个有效的<code>recover</code>调用将最新产生并且尚未恢复的恐慌和与此恐慌相关联的函数调用（即爷调用）剥离开来，并且返回当初传递给产生此恐慌的<code>panic</code>函数调用的参数。
</div>

</div>





